Internal Server Error: /api/accounts/register/
Traceback (most recent call last):
  File "C:\Users\Oðuzhan\hata_yakalama\venv\Lib\site-packages\django\db\backends\utils.py", line 105, in _execute
    return self.cursor.execute(sql, params)
           ^^^^^^^^^^^^^^^^^^^^^^^^^^^^^^^^
psycopg2.errors.UniqueViolation: duplicate key value violates unique constraint "accounts_customuser_username_key"
DETAIL:  Key (username)=(Oguzhan) already exists.


The above exception was the direct cause of the following exception:

Traceback (most recent call last):
  File "C:\Users\Oðuzhan\hata_yakalama\venv\Lib\site-packages\asgiref\sync.py", line 518, in thread_handler
    raise exc_info[1]
  File "C:\Users\Oðuzhan\hata_yakalama\venv\Lib\site-packages\django\core\handlers\exception.py", line 42, in inner
    response = await get_response(request)
               ^^^^^^^^^^^^^^^^^^^^^^^^^^^
  File "C:\Users\Oðuzhan\hata_yakalama\venv\Lib\site-packages\asgiref\sync.py", line 518, in thread_handler
    raise exc_info[1]
  File "C:\Users\Oðuzhan\hata_yakalama\venv\Lib\site-packages\django\core\handlers\base.py", line 253, in _get_response_async
    response = await wrapped_callback(
               ^^^^^^^^^^^^^^^^^^^^^^^
  File "C:\Users\Oðuzhan\hata_yakalama\venv\Lib\site-packages\asgiref\sync.py", line 468, in __call__
    ret = await asyncio.shield(exec_coro)
          ^^^^^^^^^^^^^^^^^^^^^^^^^^^^^^^
  File "C:\Python312\Lib\concurrent\futures\thread.py", line 58, in run
    result = self.fn(*self.args, **self.kwargs)
             ^^^^^^^^^^^^^^^^^^^^^^^^^^^^^^^^^^
  File "C:\Users\Oðuzhan\hata_yakalama\venv\Lib\site-packages\asgiref\sync.py", line 522, in thread_handler
    return func(*args, **kwargs)
           ^^^^^^^^^^^^^^^^^^^^^
  File "C:\Users\Oðuzhan\hata_yakalama\venv\Lib\site-packages\django\views\decorators\csrf.py", line 65, in _view_wrapper
    return view_func(request, *args, **kwargs)
           ^^^^^^^^^^^^^^^^^^^^^^^^^^^^^^^^^^^
  File "C:\Users\Oðuzhan\hata_yakalama\venv\Lib\site-packages\django\views\generic\base.py", line 104, in view
    return self.dispatch(request, *args, **kwargs)
           ^^^^^^^^^^^^^^^^^^^^^^^^^^^^^^^^^^^^^^^
  File "C:\Users\Oðuzhan\hata_yakalama\venv\Lib\site-packages\rest_framework\views.py", line 515, in dispatch
    response = self.handle_exception(exc)
               ^^^^^^^^^^^^^^^^^^^^^^^^^^
  File "C:\Users\Oðuzhan\hata_yakalama\venv\Lib\site-packages\rest_framework\views.py", line 475, in handle_exception
    self.raise_uncaught_exception(exc)
  File "C:\Users\Oðuzhan\hata_yakalama\venv\Lib\site-packages\rest_framework\views.py", line 486, in raise_uncaught_exception
    raise exc
  File "C:\Users\Oðuzhan\hata_yakalama\venv\Lib\site-packages\rest_framework\views.py", line 512, in dispatch
    response = handler(request, *args, **kwargs)
               ^^^^^^^^^^^^^^^^^^^^^^^^^^^^^^^^^
  File "C:\Users\Oðuzhan\hata_yakalama\venv\Lib\site-packages\rest_framework\generics.py", line 194, in post
    return self.create(request, *args, **kwargs)
           ^^^^^^^^^^^^^^^^^^^^^^^^^^^^^^^^^^^^^
  File "C:\Users\Oðuzhan\hata_yakalama\venv\Lib\site-packages\rest_framework\mixins.py", line 19, in create
    self.perform_create(serializer)
  File "C:\Users\Oðuzhan\hata_yakalama\venv\Lib\site-packages\rest_framework\mixins.py", line 24, in perform_create
    serializer.save()
  File "C:\Users\Oðuzhan\hata_yakalama\venv\Lib\site-packages\rest_framework\serializers.py", line 210, in save
    self.instance = self.create(validated_data)
                    ^^^^^^^^^^^^^^^^^^^^^^^^^^^
  File "C:\Users\Oðuzhan\hata_yakalama\accounts\serializers.py", line 15, in create
    user = CustomUser.objects.create_user(**validated_data)
           ^^^^^^^^^^^^^^^^^^^^^^^^^^^^^^^^^^^^^^^^^^^^^^^^
  File "C:\Users\Oðuzhan\hata_yakalama\venv\Lib\site-packages\django\contrib\auth\models.py", line 175, in create_user
    return self._create_user(username, email, password, **extra_fields)
           ^^^^^^^^^^^^^^^^^^^^^^^^^^^^^^^^^^^^^^^^^^^^^^^^^^^^^^^^^^^^
  File "C:\Users\Oðuzhan\hata_yakalama\venv\Lib\site-packages\django\contrib\auth\models.py", line 163, in _create_user
    user.save(using=self._db)
  File "C:\Users\Oðuzhan\hata_yakalama\venv\Lib\site-packages\django\contrib\auth\base_user.py", line 65, in save
    super().save(*args, **kwargs)
  File "C:\Users\Oðuzhan\hata_yakalama\venv\Lib\site-packages\django\db\models\base.py", line 902, in save
    self.save_base(
  File "C:\Users\Oðuzhan\hata_yakalama\venv\Lib\site-packages\django\db\models\base.py", line 1008, in save_base
    updated = self._save_table(
              ^^^^^^^^^^^^^^^^^
  File "C:\Users\Oðuzhan\hata_yakalama\venv\Lib\site-packages\django\db\models\base.py", line 1169, in _save_table
    results = self._do_insert(
              ^^^^^^^^^^^^^^^^
  File "C:\Users\Oðuzhan\hata_yakalama\venv\Lib\site-packages\django\db\models\base.py", line 1210, in _do_insert
    return manager._insert(
           ^^^^^^^^^^^^^^^^
  File "C:\Users\Oðuzhan\hata_yakalama\venv\Lib\site-packages\django\db\models\manager.py", line 87, in manager_method
    return getattr(self.get_queryset(), name)(*args, **kwargs)
           ^^^^^^^^^^^^^^^^^^^^^^^^^^^^^^^^^^^^^^^^^^^^^^^^^^^
  File "C:\Users\Oðuzhan\hata_yakalama\venv\Lib\site-packages\django\db\models\query.py", line 1854, in _insert
    return query.get_compiler(using=using).execute_sql(returning_fields)
           ^^^^^^^^^^^^^^^^^^^^^^^^^^^^^^^^^^^^^^^^^^^^^^^^^^^^^^^^^^^^^
  File "C:\Users\Oðuzhan\hata_yakalama\venv\Lib\site-packages\django\db\models\sql\compiler.py", line 1881, in execute_sql
    cursor.execute(sql, params)
  File "C:\Users\Oðuzhan\hata_yakalama\venv\Lib\site-packages\django\db\backends\utils.py", line 122, in execute
    return super().execute(sql, params)
           ^^^^^^^^^^^^^^^^^^^^^^^^^^^^
  File "C:\Users\Oðuzhan\hata_yakalama\venv\Lib\site-packages\django\db\backends\utils.py", line 79, in execute
    return self._execute_with_wrappers(
           ^^^^^^^^^^^^^^^^^^^^^^^^^^^^
  File "C:\Users\Oðuzhan\hata_yakalama\venv\Lib\site-packages\django\db\backends\utils.py", line 92, in _execute_with_wrappers
    return executor(sql, params, many, context)
           ^^^^^^^^^^^^^^^^^^^^^^^^^^^^^^^^^^^^
  File "C:\Users\Oðuzhan\hata_yakalama\venv\Lib\site-packages\django\db\backends\utils.py", line 100, in _execute
    with self.db.wrap_database_errors:
         ^^^^^^^^^^^^^^^^^^^^^^^^^^^^
  File "C:\Users\Oðuzhan\hata_yakalama\venv\Lib\site-packages\django\db\utils.py", line 91, in __exit__
    raise dj_exc_value.with_traceback(traceback) from exc_value
  File "C:\Users\Oðuzhan\hata_yakalama\venv\Lib\site-packages\django\db\backends\utils.py", line 105, in _execute
    return self.cursor.execute(sql, params)
           ^^^^^^^^^^^^^^^^^^^^^^^^^^^^^^^^
django.db.utils.IntegrityError: duplicate key value violates unique constraint "accounts_customuser_username_key"
DETAIL:  Key (username)=(Oguzhan) already exists.

Forbidden: /api/accounts/login/
Forbidden: /api/accounts/login/
Forbidden: /api/accounts/register/
Forbidden: /api/accounts/register/
Forbidden: /api/accounts/login/
Not Found: /static/admin/css/dark_mode.css
Not Found: /static/admin/css/base.css
Not Found: /static/admin/js/theme.js
Not Found: /static/admin/css/nav_sidebar.css
Not Found: /static/admin/css/login.css
Not Found: /static/admin/css/responsive.css
Not Found: /static/admin/js/nav_sidebar.js
Not Found: /favicon.ico
Not Found: /static/admin/css/base.css
Not Found: /static/admin/css/dark_mode.css
Not Found: /static/admin/css/login.css
Not Found: /static/admin/js/theme.js
Not Found: /static/admin/css/nav_sidebar.css
Not Found: /static/admin/css/responsive.css
Not Found: /static/admin/js/nav_sidebar.js
Not Found: /static/admin/css/nav_sidebar.css
Not Found: /static/admin/css/login.css
Not Found: /static/admin/css/responsive.css
Not Found: /favicon.ico
Not Found: /static/admin/css/dark_mode.css
Not Found: /static/admin/css/base.css
Not Found: /static/admin/css/nav_sidebar.css
Not Found: /static/admin/js/theme.js
Not Found: /static/admin/css/responsive.css
Not Found: /static/admin/css/dashboard.css
Not Found: /static/admin/css/nav_sidebar.css
Not Found: /static/admin/js/nav_sidebar.js
Not Found: /static/admin/css/base.css
Not Found: /static/admin/js/theme.js
Not Found: /static/admin/css/dark_mode.css
Not Found: /static/admin/css/responsive.css
Not Found: /static/admin/css/dashboard.css
Not Found: /static/admin/css/nav_sidebar.css
Not Found: /static/admin/js/nav_sidebar.js
Not Found: /static/admin/css/base.css
Not Found: /static/admin/css/dark_mode.css
Not Found: /static/admin/css/responsive.css
Not Found: /static/admin/js/theme.js
Not Found: /static/admin/css/nav_sidebar.css
Not Found: /static/admin/css/dashboard.css
Not Found: /static/admin/css/responsive.css
Not Found: /static/admin/js/nav_sidebar.js
Forbidden: /api/accounts/login/
Forbidden: /api/accounts/login/
Forbidden: /api/accounts/login/
Forbidden: /api/accounts/register/
Forbidden: /api/accounts/login/
Method Not Allowed: /api/accounts/login/
Not Found: /static/rest_framework/css/bootstrap-tweaks.css
Not Found: /static/rest_framework/css/prettify.css
Not Found: /static/rest_framework/css/bootstrap.min.css
Not Found: /static/rest_framework/css/default.css
Not Found: /static/rest_framework/js/jquery-3.7.1.min.js
Not Found: /static/rest_framework/js/ajax-form.js
Not Found: /static/rest_framework/js/bootstrap.min.js
Not Found: /static/rest_framework/js/csrf.js
Not Found: /static/rest_framework/js/prettify-min.js
Not Found: /static/rest_framework/js/default.js
Not Found: /static/rest_framework/js/load-ajax-form.js
Not Found: /favicon.ico
Forbidden: /api/accounts/register/
Forbidden: /api/accounts/register/
Forbidden: /api/accounts/login/
Forbidden: /api/accounts/login/
Forbidden: /api/accounts/login/
Forbidden: /api/accounts/login/
Forbidden: /api/accounts/login/
Forbidden: /api/accounts/login/
Forbidden: /api/accounts/login/
Forbidden: /api/accounts/login/
Forbidden: /api/accounts/login/
Not Found: /api/accounts/logout/
Forbidden: /api/accounts/logout/
Forbidden: /api/accounts/logout/
Forbidden: /api/accounts/logout/
Forbidden: /api/accounts/logout/
Forbidden: /api/accounts/logout/
Method Not Allowed: /api/accounts/logout/
Not Found: /static/rest_framework/css/bootstrap.min.css
Not Found: /static/rest_framework/css/bootstrap-tweaks.css
Not Found: /static/rest_framework/css/prettify.css
Not Found: /static/rest_framework/css/default.css
Not Found: /static/rest_framework/js/jquery-3.7.1.min.js
Not Found: /static/rest_framework/js/ajax-form.js
Not Found: /static/rest_framework/js/csrf.js
Not Found: /static/rest_framework/js/bootstrap.min.js
Not Found: /static/rest_framework/js/prettify-min.js
Not Found: /static/rest_framework/js/load-ajax-form.js
Not Found: /static/rest_framework/js/default.js
Not Found: /favicon.ico
Forbidden: /api/accounts/logout/
Forbidden: /api/accounts/logout/
Forbidden: /api/accounts/logout/
Forbidden: /api/accounts/logout/
Method Not Allowed: /api/accounts/logout/
Not Found: /static/rest_framework/css/bootstrap.min.css
Not Found: /static/rest_framework/css/bootstrap-tweaks.css
Not Found: /static/rest_framework/css/prettify.css
Not Found: /static/rest_framework/css/default.css
Not Found: /static/rest_framework/js/ajax-form.js
Not Found: /static/rest_framework/js/jquery-3.7.1.min.js
Not Found: /static/rest_framework/js/csrf.js
Not Found: /static/rest_framework/js/bootstrap.min.js
Not Found: /static/rest_framework/js/prettify-min.js
Not Found: /static/rest_framework/js/default.js
Not Found: /static/rest_framework/js/load-ajax-form.js
Not Found: /api/errors
Not Found: /api/errors
Internal Server Error: /api/errors
Traceback (most recent call last):
  File "C:\Users\Seray\hatayakalama\venv\Lib\site-packages\asgiref\sync.py", line 518, in thread_handler
    raise exc_info[1]
  File "C:\Users\Seray\hatayakalama\venv\Lib\site-packages\django\core\handlers\exception.py", line 42, in inner
    response = await get_response(request)
               ^^^^^^^^^^^^^^^^^^^^^^^^^^^
  File "C:\Users\Seray\hatayakalama\venv\Lib\site-packages\django\utils\deprecation.py", line 138, in __acall__
    response = await sync_to_async(
               ^^^^^^^^^^^^^^^^^^^^
    ...<2 lines>...
    )(request, response)
    ^^^^^^^^^^^^^^^^^^^^
  File "C:\Users\Seray\hatayakalama\venv\Lib\site-packages\asgiref\sync.py", line 468, in __call__
    ret = await asyncio.shield(exec_coro)
          ^^^^^^^^^^^^^^^^^^^^^^^^^^^^^^^
  File "C:\Users\Seray\AppData\Local\Programs\Python\Python313\Lib\concurrent\futures\thread.py", line 58, in run
    result = self.fn(*self.args, **self.kwargs)
  File "C:\Users\Seray\hatayakalama\venv\Lib\site-packages\asgiref\sync.py", line 522, in thread_handler
    return func(*args, **kwargs)
  File "C:\Users\Seray\hatayakalama\venv\Lib\site-packages\django\middleware\common.py", line 108, in process_response
    return self.response_redirect_class(self.get_full_path_with_slash(request))
                                        ~~~~~~~~~~~~~~~~~~~~~~~~~~~~~^^^^^^^^^
  File "C:\Users\Seray\hatayakalama\venv\Lib\site-packages\django\middleware\common.py", line 87, in get_full_path_with_slash
    raise RuntimeError(
    ...<9 lines>...
    )
RuntimeError: You called this URL via POST, but the URL doesn't end in a slash and you have APPEND_SLASH set. Django can't redirect to the slash URL while maintaining POST data. Change your form to point to localhost:8000/api/errors/ (note the trailing slash), or set APPEND_SLASH=False in your Django settings.
Internal Server Error: /api/errors
Traceback (most recent call last):
  File "C:\Users\Seray\hatayakalama\venv\Lib\site-packages\asgiref\sync.py", line 518, in thread_handler
    raise exc_info[1]
  File "C:\Users\Seray\hatayakalama\venv\Lib\site-packages\django\core\handlers\exception.py", line 42, in inner
    response = await get_response(request)
               ^^^^^^^^^^^^^^^^^^^^^^^^^^^
  File "C:\Users\Seray\hatayakalama\venv\Lib\site-packages\django\utils\deprecation.py", line 138, in __acall__
    response = await sync_to_async(
               ^^^^^^^^^^^^^^^^^^^^
    ...<2 lines>...
    )(request, response)
    ^^^^^^^^^^^^^^^^^^^^
  File "C:\Users\Seray\hatayakalama\venv\Lib\site-packages\asgiref\sync.py", line 468, in __call__
    ret = await asyncio.shield(exec_coro)
          ^^^^^^^^^^^^^^^^^^^^^^^^^^^^^^^
  File "C:\Users\Seray\AppData\Local\Programs\Python\Python313\Lib\concurrent\futures\thread.py", line 58, in run
    result = self.fn(*self.args, **self.kwargs)
  File "C:\Users\Seray\hatayakalama\venv\Lib\site-packages\asgiref\sync.py", line 522, in thread_handler
    return func(*args, **kwargs)
  File "C:\Users\Seray\hatayakalama\venv\Lib\site-packages\django\middleware\common.py", line 108, in process_response
    return self.response_redirect_class(self.get_full_path_with_slash(request))
                                        ~~~~~~~~~~~~~~~~~~~~~~~~~~~~~^^^^^^^^^
  File "C:\Users\Seray\hatayakalama\venv\Lib\site-packages\django\middleware\common.py", line 87, in get_full_path_with_slash
    raise RuntimeError(
    ...<9 lines>...
    )
RuntimeError: You called this URL via POST, but the URL doesn't end in a slash and you have APPEND_SLASH set. Django can't redirect to the slash URL while maintaining POST data. Change your form to point to localhost:8000/api/errors/ (note the trailing slash), or set APPEND_SLASH=False in your Django settings.
Internal Server Error: /api/errors
Traceback (most recent call last):
  File "C:\Users\Seray\hatayakalama\venv\Lib\site-packages\asgiref\sync.py", line 518, in thread_handler
    raise exc_info[1]
  File "C:\Users\Seray\hatayakalama\venv\Lib\site-packages\django\core\handlers\exception.py", line 42, in inner
    response = await get_response(request)
               ^^^^^^^^^^^^^^^^^^^^^^^^^^^
  File "C:\Users\Seray\hatayakalama\venv\Lib\site-packages\django\utils\deprecation.py", line 138, in __acall__
    response = await sync_to_async(
               ^^^^^^^^^^^^^^^^^^^^
    ...<2 lines>...
    )(request, response)
    ^^^^^^^^^^^^^^^^^^^^
  File "C:\Users\Seray\hatayakalama\venv\Lib\site-packages\asgiref\sync.py", line 468, in __call__
    ret = await asyncio.shield(exec_coro)
          ^^^^^^^^^^^^^^^^^^^^^^^^^^^^^^^
  File "C:\Users\Seray\AppData\Local\Programs\Python\Python313\Lib\concurrent\futures\thread.py", line 58, in run
    result = self.fn(*self.args, **self.kwargs)
  File "C:\Users\Seray\hatayakalama\venv\Lib\site-packages\asgiref\sync.py", line 522, in thread_handler
    return func(*args, **kwargs)
  File "C:\Users\Seray\hatayakalama\venv\Lib\site-packages\django\middleware\common.py", line 108, in process_response
    return self.response_redirect_class(self.get_full_path_with_slash(request))
                                        ~~~~~~~~~~~~~~~~~~~~~~~~~~~~~^^^^^^^^^
  File "C:\Users\Seray\hatayakalama\venv\Lib\site-packages\django\middleware\common.py", line 87, in get_full_path_with_slash
    raise RuntimeError(
    ...<9 lines>...
    )
RuntimeError: You called this URL via POST, but the URL doesn't end in a slash and you have APPEND_SLASH set. Django can't redirect to the slash URL while maintaining POST data. Change your form to point to localhost:8000/api/errors/ (note the trailing slash), or set APPEND_SLASH=False in your Django settings.
Internal Server Error: /api/errors
Traceback (most recent call last):
  File "C:\Users\Seray\hatayakalama\venv\Lib\site-packages\asgiref\sync.py", line 518, in thread_handler
    raise exc_info[1]
  File "C:\Users\Seray\hatayakalama\venv\Lib\site-packages\django\core\handlers\exception.py", line 42, in inner
    response = await get_response(request)
               ^^^^^^^^^^^^^^^^^^^^^^^^^^^
  File "C:\Users\Seray\hatayakalama\venv\Lib\site-packages\django\utils\deprecation.py", line 138, in __acall__
    response = await sync_to_async(
               ^^^^^^^^^^^^^^^^^^^^
    ...<2 lines>...
    )(request, response)
    ^^^^^^^^^^^^^^^^^^^^
  File "C:\Users\Seray\hatayakalama\venv\Lib\site-packages\asgiref\sync.py", line 468, in __call__
    ret = await asyncio.shield(exec_coro)
          ^^^^^^^^^^^^^^^^^^^^^^^^^^^^^^^
  File "C:\Users\Seray\AppData\Local\Programs\Python\Python313\Lib\concurrent\futures\thread.py", line 58, in run
    result = self.fn(*self.args, **self.kwargs)
  File "C:\Users\Seray\hatayakalama\venv\Lib\site-packages\asgiref\sync.py", line 522, in thread_handler
    return func(*args, **kwargs)
  File "C:\Users\Seray\hatayakalama\venv\Lib\site-packages\django\middleware\common.py", line 108, in process_response
    return self.response_redirect_class(self.get_full_path_with_slash(request))
                                        ~~~~~~~~~~~~~~~~~~~~~~~~~~~~~^^^^^^^^^
  File "C:\Users\Seray\hatayakalama\venv\Lib\site-packages\django\middleware\common.py", line 87, in get_full_path_with_slash
    raise RuntimeError(
    ...<9 lines>...
    )
RuntimeError: You called this URL via POST, but the URL doesn't end in a slash and you have APPEND_SLASH set. Django can't redirect to the slash URL while maintaining POST data. Change your form to point to localhost:8000/api/errors/ (note the trailing slash), or set APPEND_SLASH=False in your Django settings.
Internal Server Error: /api/errors
Traceback (most recent call last):
  File "C:\Users\Seray\hatayakalama\venv\Lib\site-packages\asgiref\sync.py", line 518, in thread_handler
    raise exc_info[1]
  File "C:\Users\Seray\hatayakalama\venv\Lib\site-packages\django\core\handlers\exception.py", line 42, in inner
    response = await get_response(request)
               ^^^^^^^^^^^^^^^^^^^^^^^^^^^
  File "C:\Users\Seray\hatayakalama\venv\Lib\site-packages\django\utils\deprecation.py", line 138, in __acall__
    response = await sync_to_async(
               ^^^^^^^^^^^^^^^^^^^^
    ...<2 lines>...
    )(request, response)
    ^^^^^^^^^^^^^^^^^^^^
  File "C:\Users\Seray\hatayakalama\venv\Lib\site-packages\asgiref\sync.py", line 468, in __call__
    ret = await asyncio.shield(exec_coro)
          ^^^^^^^^^^^^^^^^^^^^^^^^^^^^^^^
  File "C:\Users\Seray\AppData\Local\Programs\Python\Python313\Lib\concurrent\futures\thread.py", line 58, in run
    result = self.fn(*self.args, **self.kwargs)
  File "C:\Users\Seray\hatayakalama\venv\Lib\site-packages\asgiref\sync.py", line 522, in thread_handler
    return func(*args, **kwargs)
  File "C:\Users\Seray\hatayakalama\venv\Lib\site-packages\django\middleware\common.py", line 108, in process_response
    return self.response_redirect_class(self.get_full_path_with_slash(request))
                                        ~~~~~~~~~~~~~~~~~~~~~~~~~~~~~^^^^^^^^^
  File "C:\Users\Seray\hatayakalama\venv\Lib\site-packages\django\middleware\common.py", line 87, in get_full_path_with_slash
    raise RuntimeError(
    ...<9 lines>...
    )
RuntimeError: You called this URL via POST, but the URL doesn't end in a slash and you have APPEND_SLASH set. Django can't redirect to the slash URL while maintaining POST data. Change your form to point to localhost:8000/api/errors/ (note the trailing slash), or set APPEND_SLASH=False in your Django settings.
Internal Server Error: /api/errors
Traceback (most recent call last):
  File "C:\Users\Seray\hatayakalama\venv\Lib\site-packages\asgiref\sync.py", line 518, in thread_handler
    raise exc_info[1]
  File "C:\Users\Seray\hatayakalama\venv\Lib\site-packages\django\core\handlers\exception.py", line 42, in inner
    response = await get_response(request)
               ^^^^^^^^^^^^^^^^^^^^^^^^^^^
  File "C:\Users\Seray\hatayakalama\venv\Lib\site-packages\django\utils\deprecation.py", line 138, in __acall__
    response = await sync_to_async(
               ^^^^^^^^^^^^^^^^^^^^
    ...<2 lines>...
    )(request, response)
    ^^^^^^^^^^^^^^^^^^^^
  File "C:\Users\Seray\hatayakalama\venv\Lib\site-packages\asgiref\sync.py", line 468, in __call__
    ret = await asyncio.shield(exec_coro)
          ^^^^^^^^^^^^^^^^^^^^^^^^^^^^^^^
  File "C:\Users\Seray\AppData\Local\Programs\Python\Python313\Lib\concurrent\futures\thread.py", line 58, in run
    result = self.fn(*self.args, **self.kwargs)
  File "C:\Users\Seray\hatayakalama\venv\Lib\site-packages\asgiref\sync.py", line 522, in thread_handler
    return func(*args, **kwargs)
  File "C:\Users\Seray\hatayakalama\venv\Lib\site-packages\django\middleware\common.py", line 108, in process_response
    return self.response_redirect_class(self.get_full_path_with_slash(request))
                                        ~~~~~~~~~~~~~~~~~~~~~~~~~~~~~^^^^^^^^^
  File "C:\Users\Seray\hatayakalama\venv\Lib\site-packages\django\middleware\common.py", line 87, in get_full_path_with_slash
    raise RuntimeError(
    ...<9 lines>...
    )
RuntimeError: You called this URL via POST, but the URL doesn't end in a slash and you have APPEND_SLASH set. Django can't redirect to the slash URL while maintaining POST data. Change your form to point to localhost:8000/api/errors/ (note the trailing slash), or set APPEND_SLASH=False in your Django settings.
Forbidden: /api/errors/
Forbidden: /api/errors/
Forbidden: /api/errors/
Forbidden: /api/errors/
Forbidden: /api/errors/
Forbidden: /api/errors/
Forbidden: /api/errors/
Not Found: /api/users/
Forbidden: /api/errors/
Bad Request: /api/errors/
Bad Request: /api/errors/
Bad Request: /api/errors/
Unauthorized: /api/accounts/login/
Unauthorized: /api/accounts/login/
Unauthorized: /api/accounts/login/
Unauthorized: /api/accounts/login/
Unauthorized: /api/accounts/login/
Unauthorized: /api/accounts/login/
Unauthorized: /api/accounts/login/
Unauthorized: /api/accounts/login/
Unauthorized: /api/accounts/login/
Unauthorized: /api/accounts/login/
Unauthorized: /api/accounts/login/
Unauthorized: /api/accounts/login/
Unauthorized: /api/accounts/login/
Unauthorized: /api/accounts/login/
Unauthorized: /api/accounts/login/
Unauthorized: /api/accounts/login/
Unauthorized: /api/accounts/login/
Not Found: /api/errors/1/
Not Found: /api/errors/2/
Not Found: /api/errors/1/
Not Found: /api/errors/2/
Not Found: /api/errors/2/
Not Found: /api/errors/1/
Not Found: /api/errors/1/
Not Found: /api/errors/1/
Not Found: /api/errors/1/
Not Found: /api/errors/1
Not Found: /api/errors/1
Not Found: /api/errors/1/
Not Found: /api/errors/1/
Not Found: /api/errors/1/
Not Found: /api/errors/1/
Not Found: /api/users/
Not Found: /api/users/
Not Found: /api/users/
Not Found: /api/users/
Not Found: /api/users/
Not Found: /api/users/
Bad Request: /api/accounts/register/
Internal Server Error: /api/accounts/register/
Traceback (most recent call last):
  File "C:\Users\Seray\hatayakalama\venv\Lib\site-packages\django\db\backends\utils.py", line 105, in _execute
    return self.cursor.execute(sql, params)
           ~~~~~~~~~~~~~~~~~~~^^^^^^^^^^^^^
psycopg2.errors.UniqueViolation: HATA:  tekrar eden kayýt, "accounts_customuser_username_key" tekil kýsýtlamasýný ihlal etmektedir
DETAIL:  "(username)=(ozi)" anahtarý zaten mevcut


The above exception was the direct cause of the following exception:

Traceback (most recent call last):
  File "C:\Users\Seray\hatayakalama\venv\Lib\site-packages\asgiref\sync.py", line 518, in thread_handler
    raise exc_info[1]
  File "C:\Users\Seray\hatayakalama\venv\Lib\site-packages\django\core\handlers\exception.py", line 42, in inner
    response = await get_response(request)
               ^^^^^^^^^^^^^^^^^^^^^^^^^^^
  File "C:\Users\Seray\hatayakalama\venv\Lib\site-packages\asgiref\sync.py", line 518, in thread_handler
    raise exc_info[1]
  File "C:\Users\Seray\hatayakalama\venv\Lib\site-packages\django\core\handlers\base.py", line 253, in _get_response_async
    response = await wrapped_callback(
               ^^^^^^^^^^^^^^^^^^^^^^^
        request, *callback_args, **callback_kwargs
        ^^^^^^^^^^^^^^^^^^^^^^^^^^^^^^^^^^^^^^^^^^
    )
    ^
  File "C:\Users\Seray\hatayakalama\venv\Lib\site-packages\asgiref\sync.py", line 468, in __call__
    ret = await asyncio.shield(exec_coro)
          ^^^^^^^^^^^^^^^^^^^^^^^^^^^^^^^
  File "C:\Users\Seray\AppData\Local\Programs\Python\Python313\Lib\concurrent\futures\thread.py", line 58, in run
    result = self.fn(*self.args, **self.kwargs)
  File "C:\Users\Seray\hatayakalama\venv\Lib\site-packages\asgiref\sync.py", line 522, in thread_handler
    return func(*args, **kwargs)
  File "C:\Users\Seray\hatayakalama\venv\Lib\site-packages\django\views\decorators\csrf.py", line 65, in _view_wrapper
    return view_func(request, *args, **kwargs)
  File "C:\Users\Seray\hatayakalama\venv\Lib\site-packages\django\views\generic\base.py", line 104, in view
    return self.dispatch(request, *args, **kwargs)
           ~~~~~~~~~~~~~^^^^^^^^^^^^^^^^^^^^^^^^^^
  File "C:\Users\Seray\hatayakalama\venv\Lib\site-packages\rest_framework\views.py", line 515, in dispatch
    response = self.handle_exception(exc)
  File "C:\Users\Seray\hatayakalama\venv\Lib\site-packages\rest_framework\views.py", line 475, in handle_exception
    self.raise_uncaught_exception(exc)
    ~~~~~~~~~~~~~~~~~~~~~~~~~~~~~^^^^^
  File "C:\Users\Seray\hatayakalama\venv\Lib\site-packages\rest_framework\views.py", line 486, in raise_uncaught_exception
    raise exc
  File "C:\Users\Seray\hatayakalama\venv\Lib\site-packages\rest_framework\views.py", line 512, in dispatch
    response = handler(request, *args, **kwargs)
  File "C:\Users\Seray\hatayakalama\venv\Lib\site-packages\rest_framework\generics.py", line 194, in post
    return self.create(request, *args, **kwargs)
           ~~~~~~~~~~~^^^^^^^^^^^^^^^^^^^^^^^^^^
  File "C:\Users\Seray\hatayakalama\venv\Lib\site-packages\rest_framework\mixins.py", line 19, in create
    self.perform_create(serializer)
    ~~~~~~~~~~~~~~~~~~~^^^^^^^^^^^^
  File "C:\Users\Seray\hatayakalama\venv\Lib\site-packages\rest_framework\mixins.py", line 24, in perform_create
    serializer.save()
    ~~~~~~~~~~~~~~~^^
  File "C:\Users\Seray\hatayakalama\venv\Lib\site-packages\rest_framework\serializers.py", line 210, in save
    self.instance = self.create(validated_data)
                    ~~~~~~~~~~~^^^^^^^^^^^^^^^^
  File "C:\Users\Seray\hatayakalama\accounts\serializers.py", line 15, in create
    user = CustomUser.objects.create_user(**validated_data)
  File "C:\Users\Seray\hatayakalama\venv\Lib\site-packages\django\contrib\auth\models.py", line 175, in create_user
    return self._create_user(username, email, password, **extra_fields)
           ~~~~~~~~~~~~~~~~~^^^^^^^^^^^^^^^^^^^^^^^^^^^^^^^^^^^^^^^^^^^
  File "C:\Users\Seray\hatayakalama\venv\Lib\site-packages\django\contrib\auth\models.py", line 163, in _create_user
    user.save(using=self._db)
    ~~~~~~~~~^^^^^^^^^^^^^^^^
  File "C:\Users\Seray\hatayakalama\venv\Lib\site-packages\django\contrib\auth\base_user.py", line 65, in save
    super().save(*args, **kwargs)
    ~~~~~~~~~~~~^^^^^^^^^^^^^^^^^
  File "C:\Users\Seray\hatayakalama\venv\Lib\site-packages\django\db\models\base.py", line 902, in save
    self.save_base(
    ~~~~~~~~~~~~~~^
        using=using,
        ^^^^^^^^^^^^
    ...<2 lines>...
        update_fields=update_fields,
        ^^^^^^^^^^^^^^^^^^^^^^^^^^^^
    )
    ^
  File "C:\Users\Seray\hatayakalama\venv\Lib\site-packages\django\db\models\base.py", line 1008, in save_base
    updated = self._save_table(
        raw,
    ...<4 lines>...
        update_fields,
    )
  File "C:\Users\Seray\hatayakalama\venv\Lib\site-packages\django\db\models\base.py", line 1169, in _save_table
    results = self._do_insert(
        cls._base_manager, using, fields, returning_fields, raw
    )
  File "C:\Users\Seray\hatayakalama\venv\Lib\site-packages\django\db\models\base.py", line 1210, in _do_insert
    return manager._insert(
           ~~~~~~~~~~~~~~~^
        [self],
        ^^^^^^^
    ...<3 lines>...
        raw=raw,
        ^^^^^^^^
    )
    ^
  File "C:\Users\Seray\hatayakalama\venv\Lib\site-packages\django\db\models\manager.py", line 87, in manager_method
    return getattr(self.get_queryset(), name)(*args, **kwargs)
           ~~~~~~~~~~~~~~~~~~~~~~~~~~~~~~~~~~^^^^^^^^^^^^^^^^^
  File "C:\Users\Seray\hatayakalama\venv\Lib\site-packages\django\db\models\query.py", line 1854, in _insert
    return query.get_compiler(using=using).execute_sql(returning_fields)
           ~~~~~~~~~~~~~~~~~~~~~~~~~~~~~~~~~~~~~~~~~~~^^^^^^^^^^^^^^^^^^
  File "C:\Users\Seray\hatayakalama\venv\Lib\site-packages\django\db\models\sql\compiler.py", line 1881, in execute_sql
    cursor.execute(sql, params)
    ~~~~~~~~~~~~~~^^^^^^^^^^^^^
  File "C:\Users\Seray\hatayakalama\venv\Lib\site-packages\django\db\backends\utils.py", line 122, in execute
    return super().execute(sql, params)
           ~~~~~~~~~~~~~~~^^^^^^^^^^^^^
  File "C:\Users\Seray\hatayakalama\venv\Lib\site-packages\django\db\backends\utils.py", line 79, in execute
    return self._execute_with_wrappers(
           ~~~~~~~~~~~~~~~~~~~~~~~~~~~^
        sql, params, many=False, executor=self._execute
        ^^^^^^^^^^^^^^^^^^^^^^^^^^^^^^^^^^^^^^^^^^^^^^^
    )
    ^
  File "C:\Users\Seray\hatayakalama\venv\Lib\site-packages\django\db\backends\utils.py", line 92, in _execute_with_wrappers
    return executor(sql, params, many, context)
  File "C:\Users\Seray\hatayakalama\venv\Lib\site-packages\django\db\backends\utils.py", line 100, in _execute
    with self.db.wrap_database_errors:
         ^^^^^^^^^^^^^^^^^^^^^^^^^^^^
  File "C:\Users\Seray\hatayakalama\venv\Lib\site-packages\django\db\utils.py", line 91, in __exit__
    raise dj_exc_value.with_traceback(traceback) from exc_value
  File "C:\Users\Seray\hatayakalama\venv\Lib\site-packages\django\db\backends\utils.py", line 105, in _execute
    return self.cursor.execute(sql, params)
           ~~~~~~~~~~~~~~~~~~~^^^^^^^^^^^^^
django.db.utils.IntegrityError: HATA:  tekrar eden kayýt, "accounts_customuser_username_key" tekil kýsýtlamasýný ihlal etmektedir
DETAIL:  "(username)=(ozi)" anahtarý zaten mevcut

Internal Server Error: /api/accounts/
Traceback (most recent call last):
  File "C:\Users\Seray\hatayakalama\venv\Lib\site-packages\asgiref\sync.py", line 518, in thread_handler
    raise exc_info[1]
  File "C:\Users\Seray\hatayakalama\venv\Lib\site-packages\django\core\handlers\exception.py", line 42, in inner
    response = await get_response(request)
               ^^^^^^^^^^^^^^^^^^^^^^^^^^^
  File "C:\Users\Seray\hatayakalama\venv\Lib\site-packages\asgiref\sync.py", line 518, in thread_handler
    raise exc_info[1]
  File "C:\Users\Seray\hatayakalama\venv\Lib\site-packages\django\core\handlers\base.py", line 253, in _get_response_async
    response = await wrapped_callback(
               ^^^^^^^^^^^^^^^^^^^^^^^
        request, *callback_args, **callback_kwargs
        ^^^^^^^^^^^^^^^^^^^^^^^^^^^^^^^^^^^^^^^^^^
    )
    ^
  File "C:\Users\Seray\hatayakalama\venv\Lib\site-packages\asgiref\sync.py", line 468, in __call__
    ret = await asyncio.shield(exec_coro)
          ^^^^^^^^^^^^^^^^^^^^^^^^^^^^^^^
  File "C:\Users\Seray\AppData\Local\Programs\Python\Python313\Lib\concurrent\futures\thread.py", line 58, in run
    result = self.fn(*self.args, **self.kwargs)
  File "C:\Users\Seray\hatayakalama\venv\Lib\site-packages\asgiref\sync.py", line 522, in thread_handler
    return func(*args, **kwargs)
  File "C:\Users\Seray\hatayakalama\venv\Lib\site-packages\django\views\decorators\csrf.py", line 65, in _view_wrapper
    return view_func(request, *args, **kwargs)
  File "C:\Users\Seray\hatayakalama\venv\Lib\site-packages\django\views\generic\base.py", line 104, in view
    return self.dispatch(request, *args, **kwargs)
           ~~~~~~~~~~~~~^^^^^^^^^^^^^^^^^^^^^^^^^^
  File "C:\Users\Seray\hatayakalama\venv\Lib\site-packages\rest_framework\views.py", line 515, in dispatch
    response = self.handle_exception(exc)
  File "C:\Users\Seray\hatayakalama\venv\Lib\site-packages\rest_framework\views.py", line 475, in handle_exception
    self.raise_uncaught_exception(exc)
    ~~~~~~~~~~~~~~~~~~~~~~~~~~~~~^^^^^
  File "C:\Users\Seray\hatayakalama\venv\Lib\site-packages\rest_framework\views.py", line 486, in raise_uncaught_exception
    raise exc
  File "C:\Users\Seray\hatayakalama\venv\Lib\site-packages\rest_framework\views.py", line 512, in dispatch
    response = handler(request, *args, **kwargs)
  File "C:\Users\Seray\hatayakalama\venv\Lib\site-packages\rest_framework\generics.py", line 203, in get
    return self.list(request, *args, **kwargs)
           ~~~~~~~~~^^^^^^^^^^^^^^^^^^^^^^^^^^
  File "C:\Users\Seray\hatayakalama\venv\Lib\site-packages\rest_framework\mixins.py", line 46, in list
    return Response(serializer.data)
                    ^^^^^^^^^^^^^^^
  File "C:\Users\Seray\hatayakalama\venv\Lib\site-packages\rest_framework\serializers.py", line 797, in data
    ret = super().data
          ^^^^^^^^^^^^
  File "C:\Users\Seray\hatayakalama\venv\Lib\site-packages\rest_framework\serializers.py", line 251, in data
    self._data = self.to_representation(self.instance)
                 ~~~~~~~~~~~~~~~~~~~~~~^^^^^^^^^^^^^^^
  File "C:\Users\Seray\hatayakalama\venv\Lib\site-packages\rest_framework\serializers.py", line 716, in to_representation
    self.child.to_representation(item) for item in iterable
    ~~~~~~~~~~~~~~~~~~~~~~~~~~~~^^^^^^
  File "C:\Users\Seray\hatayakalama\venv\Lib\site-packages\rest_framework\serializers.py", line 525, in to_representation
    for field in fields:
                 ^^^^^^
  File "C:\Users\Seray\hatayakalama\venv\Lib\site-packages\rest_framework\serializers.py", line 386, in _readable_fields
    for field in self.fields.values():
                 ^^^^^^^^^^^
  File "C:\Users\Seray\hatayakalama\venv\Lib\site-packages\django\utils\functional.py", line 47, in __get__
    res = instance.__dict__[self.name] = self.func(instance)
                                         ~~~~~~~~~^^^^^^^^^^
  File "C:\Users\Seray\hatayakalama\venv\Lib\site-packages\rest_framework\serializers.py", line 374, in fields
    for key, value in self.get_fields().items():
                      ~~~~~~~~~~~~~~~^^
  File "C:\Users\Seray\hatayakalama\venv\Lib\site-packages\rest_framework\serializers.py", line 1105, in get_fields
    field_class, field_kwargs = self.build_field(
                                ~~~~~~~~~~~~~~~~^
        source, info, model, depth
        ^^^^^^^^^^^^^^^^^^^^^^^^^^
    )
    ^
  File "C:\Users\Seray\hatayakalama\venv\Lib\site-packages\rest_framework\serializers.py", line 1251, in build_field
    return self.build_unknown_field(field_name, model_class)
           ~~~~~~~~~~~~~~~~~~~~~~~~^^^^^^^^^^^^^^^^^^^^^^^^^
  File "C:\Users\Seray\hatayakalama\venv\Lib\site-packages\rest_framework\serializers.py", line 1369, in build_unknown_field
    raise ImproperlyConfigured(
    ...<2 lines>...
    )
django.core.exceptions.ImproperlyConfigured: Field name `last_nameemail` is not valid for model `CustomUser` in `accounts.serializers.CustomUserSerializer`.
Internal Server Error: /api/accounts/
Traceback (most recent call last):
  File "C:\Users\Seray\hatayakalama\venv\Lib\site-packages\asgiref\sync.py", line 518, in thread_handler
    raise exc_info[1]
  File "C:\Users\Seray\hatayakalama\venv\Lib\site-packages\django\core\handlers\exception.py", line 42, in inner
    response = await get_response(request)
               ^^^^^^^^^^^^^^^^^^^^^^^^^^^
  File "C:\Users\Seray\hatayakalama\venv\Lib\site-packages\asgiref\sync.py", line 518, in thread_handler
    raise exc_info[1]
  File "C:\Users\Seray\hatayakalama\venv\Lib\site-packages\django\core\handlers\base.py", line 253, in _get_response_async
    response = await wrapped_callback(
               ^^^^^^^^^^^^^^^^^^^^^^^
        request, *callback_args, **callback_kwargs
        ^^^^^^^^^^^^^^^^^^^^^^^^^^^^^^^^^^^^^^^^^^
    )
    ^
  File "C:\Users\Seray\hatayakalama\venv\Lib\site-packages\asgiref\sync.py", line 468, in __call__
    ret = await asyncio.shield(exec_coro)
          ^^^^^^^^^^^^^^^^^^^^^^^^^^^^^^^
  File "C:\Users\Seray\AppData\Local\Programs\Python\Python313\Lib\concurrent\futures\thread.py", line 58, in run
    result = self.fn(*self.args, **self.kwargs)
  File "C:\Users\Seray\hatayakalama\venv\Lib\site-packages\asgiref\sync.py", line 522, in thread_handler
    return func(*args, **kwargs)
  File "C:\Users\Seray\hatayakalama\venv\Lib\site-packages\django\views\decorators\csrf.py", line 65, in _view_wrapper
    return view_func(request, *args, **kwargs)
  File "C:\Users\Seray\hatayakalama\venv\Lib\site-packages\django\views\generic\base.py", line 104, in view
    return self.dispatch(request, *args, **kwargs)
           ~~~~~~~~~~~~~^^^^^^^^^^^^^^^^^^^^^^^^^^
  File "C:\Users\Seray\hatayakalama\venv\Lib\site-packages\rest_framework\views.py", line 515, in dispatch
    response = self.handle_exception(exc)
  File "C:\Users\Seray\hatayakalama\venv\Lib\site-packages\rest_framework\views.py", line 475, in handle_exception
    self.raise_uncaught_exception(exc)
    ~~~~~~~~~~~~~~~~~~~~~~~~~~~~~^^^^^
  File "C:\Users\Seray\hatayakalama\venv\Lib\site-packages\rest_framework\views.py", line 486, in raise_uncaught_exception
    raise exc
  File "C:\Users\Seray\hatayakalama\venv\Lib\site-packages\rest_framework\views.py", line 512, in dispatch
    response = handler(request, *args, **kwargs)
  File "C:\Users\Seray\hatayakalama\venv\Lib\site-packages\rest_framework\generics.py", line 203, in get
    return self.list(request, *args, **kwargs)
           ~~~~~~~~~^^^^^^^^^^^^^^^^^^^^^^^^^^
  File "C:\Users\Seray\hatayakalama\venv\Lib\site-packages\rest_framework\mixins.py", line 46, in list
    return Response(serializer.data)
                    ^^^^^^^^^^^^^^^
  File "C:\Users\Seray\hatayakalama\venv\Lib\site-packages\rest_framework\serializers.py", line 797, in data
    ret = super().data
          ^^^^^^^^^^^^
  File "C:\Users\Seray\hatayakalama\venv\Lib\site-packages\rest_framework\serializers.py", line 251, in data
    self._data = self.to_representation(self.instance)
                 ~~~~~~~~~~~~~~~~~~~~~~^^^^^^^^^^^^^^^
  File "C:\Users\Seray\hatayakalama\venv\Lib\site-packages\rest_framework\serializers.py", line 716, in to_representation
    self.child.to_representation(item) for item in iterable
    ~~~~~~~~~~~~~~~~~~~~~~~~~~~~^^^^^^
  File "C:\Users\Seray\hatayakalama\venv\Lib\site-packages\rest_framework\serializers.py", line 525, in to_representation
    for field in fields:
                 ^^^^^^
  File "C:\Users\Seray\hatayakalama\venv\Lib\site-packages\rest_framework\serializers.py", line 386, in _readable_fields
    for field in self.fields.values():
                 ^^^^^^^^^^^
  File "C:\Users\Seray\hatayakalama\venv\Lib\site-packages\django\utils\functional.py", line 47, in __get__
    res = instance.__dict__[self.name] = self.func(instance)
                                         ~~~~~~~~~^^^^^^^^^^
  File "C:\Users\Seray\hatayakalama\venv\Lib\site-packages\rest_framework\serializers.py", line 374, in fields
    for key, value in self.get_fields().items():
                      ~~~~~~~~~~~~~~~^^
  File "C:\Users\Seray\hatayakalama\venv\Lib\site-packages\rest_framework\serializers.py", line 1105, in get_fields
    field_class, field_kwargs = self.build_field(
                                ~~~~~~~~~~~~~~~~^
        source, info, model, depth
        ^^^^^^^^^^^^^^^^^^^^^^^^^^
    )
    ^
  File "C:\Users\Seray\hatayakalama\venv\Lib\site-packages\rest_framework\serializers.py", line 1251, in build_field
    return self.build_unknown_field(field_name, model_class)
           ~~~~~~~~~~~~~~~~~~~~~~~~^^^^^^^^^^^^^^^^^^^^^^^^^
  File "C:\Users\Seray\hatayakalama\venv\Lib\site-packages\rest_framework\serializers.py", line 1369, in build_unknown_field
    raise ImproperlyConfigured(
    ...<2 lines>...
    )
django.core.exceptions.ImproperlyConfigured: Field name `last_nameemail` is not valid for model `CustomUser` in `accounts.serializers.CustomUserSerializer`.
Internal Server Error: /api/accounts/register/
Traceback (most recent call last):
  File "C:\Users\Seray\hatayakalama\venv\Lib\site-packages\asgiref\sync.py", line 518, in thread_handler
    raise exc_info[1]
  File "C:\Users\Seray\hatayakalama\venv\Lib\site-packages\django\core\handlers\exception.py", line 42, in inner
    response = await get_response(request)
               ^^^^^^^^^^^^^^^^^^^^^^^^^^^
  File "C:\Users\Seray\hatayakalama\venv\Lib\site-packages\asgiref\sync.py", line 518, in thread_handler
    raise exc_info[1]
  File "C:\Users\Seray\hatayakalama\venv\Lib\site-packages\django\core\handlers\base.py", line 253, in _get_response_async
    response = await wrapped_callback(
               ^^^^^^^^^^^^^^^^^^^^^^^
        request, *callback_args, **callback_kwargs
        ^^^^^^^^^^^^^^^^^^^^^^^^^^^^^^^^^^^^^^^^^^
    )
    ^
  File "C:\Users\Seray\hatayakalama\venv\Lib\site-packages\asgiref\sync.py", line 468, in __call__
    ret = await asyncio.shield(exec_coro)
          ^^^^^^^^^^^^^^^^^^^^^^^^^^^^^^^
  File "C:\Users\Seray\AppData\Local\Programs\Python\Python313\Lib\concurrent\futures\thread.py", line 58, in run
    result = self.fn(*self.args, **self.kwargs)
  File "C:\Users\Seray\hatayakalama\venv\Lib\site-packages\asgiref\sync.py", line 522, in thread_handler
    return func(*args, **kwargs)
  File "C:\Users\Seray\hatayakalama\venv\Lib\site-packages\django\views\decorators\csrf.py", line 65, in _view_wrapper
    return view_func(request, *args, **kwargs)
  File "C:\Users\Seray\hatayakalama\venv\Lib\site-packages\django\views\generic\base.py", line 104, in view
    return self.dispatch(request, *args, **kwargs)
           ~~~~~~~~~~~~~^^^^^^^^^^^^^^^^^^^^^^^^^^
  File "C:\Users\Seray\hatayakalama\venv\Lib\site-packages\rest_framework\views.py", line 515, in dispatch
    response = self.handle_exception(exc)
  File "C:\Users\Seray\hatayakalama\venv\Lib\site-packages\rest_framework\views.py", line 475, in handle_exception
    self.raise_uncaught_exception(exc)
    ~~~~~~~~~~~~~~~~~~~~~~~~~~~~~^^^^^
  File "C:\Users\Seray\hatayakalama\venv\Lib\site-packages\rest_framework\views.py", line 486, in raise_uncaught_exception
    raise exc
  File "C:\Users\Seray\hatayakalama\venv\Lib\site-packages\rest_framework\views.py", line 512, in dispatch
    response = handler(request, *args, **kwargs)
  File "C:\Users\Seray\hatayakalama\venv\Lib\site-packages\rest_framework\generics.py", line 194, in post
    return self.create(request, *args, **kwargs)
           ~~~~~~~~~~~^^^^^^^^^^^^^^^^^^^^^^^^^^
  File "C:\Users\Seray\hatayakalama\venv\Lib\site-packages\rest_framework\mixins.py", line 18, in create
    serializer.is_valid(raise_exception=True)
    ~~~~~~~~~~~~~~~~~~~^^^^^^^^^^^^^^^^^^^^^^
  File "C:\Users\Seray\hatayakalama\venv\Lib\site-packages\rest_framework\serializers.py", line 225, in is_valid
    self._validated_data = self.run_validation(self.initial_data)
                           ~~~~~~~~~~~~~~~~~~~^^^^^^^^^^^^^^^^^^^
  File "C:\Users\Seray\hatayakalama\venv\Lib\site-packages\rest_framework\serializers.py", line 444, in run_validation
    value = self.to_internal_value(data)
  File "C:\Users\Seray\hatayakalama\venv\Lib\site-packages\rest_framework\serializers.py", line 497, in to_internal_value
    for field in fields:
                 ^^^^^^
  File "C:\Users\Seray\hatayakalama\venv\Lib\site-packages\rest_framework\serializers.py", line 380, in _writable_fields
    for field in self.fields.values():
                 ^^^^^^^^^^^
  File "C:\Users\Seray\hatayakalama\venv\Lib\site-packages\django\utils\functional.py", line 47, in __get__
    res = instance.__dict__[self.name] = self.func(instance)
                                         ~~~~~~~~~^^^^^^^^^^
  File "C:\Users\Seray\hatayakalama\venv\Lib\site-packages\rest_framework\serializers.py", line 374, in fields
    for key, value in self.get_fields().items():
                      ~~~~~~~~~~~~~~~^^
  File "C:\Users\Seray\hatayakalama\venv\Lib\site-packages\rest_framework\serializers.py", line 1105, in get_fields
    field_class, field_kwargs = self.build_field(
                                ~~~~~~~~~~~~~~~~^
        source, info, model, depth
        ^^^^^^^^^^^^^^^^^^^^^^^^^^
    )
    ^
  File "C:\Users\Seray\hatayakalama\venv\Lib\site-packages\rest_framework\serializers.py", line 1251, in build_field
    return self.build_unknown_field(field_name, model_class)
           ~~~~~~~~~~~~~~~~~~~~~~~~^^^^^^^^^^^^^^^^^^^^^^^^^
  File "C:\Users\Seray\hatayakalama\venv\Lib\site-packages\rest_framework\serializers.py", line 1369, in build_unknown_field
    raise ImproperlyConfigured(
    ...<2 lines>...
    )
django.core.exceptions.ImproperlyConfigured: Field name `last_nameemail` is not valid for model `CustomUser` in `accounts.serializers.CustomUserSerializer`.
Unauthorized: /api/accounts/login/
Bad Request: /api/accounts/register/
Bad Request: /api/accounts/9/
Bad Request: /api/accounts/9/
Unauthorized: /api/accounts/login/
Forbidden: /api/accounts/
Forbidden: /api/accounts/
Forbidden: /api/accounts/
Forbidden: /api/accounts/
Forbidden: /api/accounts/
Forbidden: /api/accounts/
Forbidden: /api/accounts/
Forbidden: /api/accounts/
Forbidden: /api/accounts/
Forbidden: /api/accounts/
Forbidden: /api/accounts/
Forbidden: /api/accounts/
Forbidden: /api/accounts/
Forbidden: /api/accounts/
Forbidden: /api/accounts/
Forbidden: /api/accounts/
Forbidden: /api/accounts/
Forbidden: /api/accounts/
Forbidden: /api/accounts/
Forbidden: /api/accounts/
